2020-05-06 14:20:27,736 ERROR: Exception on /cpu [POST] [in /home/user/.local/lib/python3.7/site-packages/flask/app.py:1891]
Traceback (most recent call last):
  File "/home/user/.local/lib/python3.7/site-packages/flask/app.py", line 2446, in wsgi_app
    response = self.full_dispatch_request()
  File "/home/user/.local/lib/python3.7/site-packages/flask/app.py", line 1951, in full_dispatch_request
    rv = self.handle_user_exception(e)
  File "/home/user/.local/lib/python3.7/site-packages/flask/app.py", line 1820, in handle_user_exception
    reraise(exc_type, exc_value, tb)
  File "/home/user/.local/lib/python3.7/site-packages/flask/_compat.py", line 39, in reraise
    raise value
  File "/home/user/.local/lib/python3.7/site-packages/flask/app.py", line 1949, in full_dispatch_request
    rv = self.dispatch_request()
  File "/home/user/.local/lib/python3.7/site-packages/flask/app.py", line 1935, in dispatch_request
    return self.view_functions[rule.endpoint](**req.view_args)
  File "/home/user/.local/lib/python3.7/site-packages/flask_login/utils.py", line 261, in decorated_view
    return func(*args, **kwargs)
  File "/home/user/Documents/Scripts/microblog/app/routes.py", line 195, in cpu
    html_text = mpld3.fig_to_html(figure)
  File "/home/user/.local/lib/python3.7/site-packages/mpld3/_display.py", line 251, in fig_to_html
    figure_json=json.dumps(figure_json, cls=NumpyEncoder),
  File "/usr/lib/python3.7/json/__init__.py", line 238, in dumps
    **kw).encode(obj)
  File "/usr/lib/python3.7/json/encoder.py", line 199, in encode
    chunks = self.iterencode(o, _one_shot=True)
  File "/usr/lib/python3.7/json/encoder.py", line 257, in iterencode
    return _iterencode(o, 0)
  File "/home/user/.local/lib/python3.7/site-packages/mpld3/_display.py", line 139, in default
    return json.JSONEncoder.default(self, obj)
  File "/usr/lib/python3.7/json/encoder.py", line 179, in default
    raise TypeError(f'Object of type {o.__class__.__name__} '
TypeError: Object of type chain is not JSON serializable
2020-05-06 14:22:41,666 ERROR: Exception on /cpu [POST] [in /home/user/.local/lib/python3.7/site-packages/flask/app.py:1891]
Traceback (most recent call last):
  File "/home/user/.local/lib/python3.7/site-packages/flask/app.py", line 2446, in wsgi_app
    response = self.full_dispatch_request()
  File "/home/user/.local/lib/python3.7/site-packages/flask/app.py", line 1951, in full_dispatch_request
    rv = self.handle_user_exception(e)
  File "/home/user/.local/lib/python3.7/site-packages/flask/app.py", line 1820, in handle_user_exception
    reraise(exc_type, exc_value, tb)
  File "/home/user/.local/lib/python3.7/site-packages/flask/_compat.py", line 39, in reraise
    raise value
  File "/home/user/.local/lib/python3.7/site-packages/flask/app.py", line 1949, in full_dispatch_request
    rv = self.dispatch_request()
  File "/home/user/.local/lib/python3.7/site-packages/flask/app.py", line 1935, in dispatch_request
    return self.view_functions[rule.endpoint](**req.view_args)
  File "/home/user/.local/lib/python3.7/site-packages/flask_login/utils.py", line 261, in decorated_view
    return func(*args, **kwargs)
  File "/home/user/Documents/Scripts/microblog/app/routes.py", line 195, in cpu
    html_text = mpld3.fig_to_html(figure)
  File "/home/user/.local/lib/python3.7/site-packages/mpld3/_display.py", line 251, in fig_to_html
    figure_json=json.dumps(figure_json, cls=NumpyEncoder),
  File "/usr/lib/python3.7/json/__init__.py", line 238, in dumps
    **kw).encode(obj)
  File "/usr/lib/python3.7/json/encoder.py", line 199, in encode
    chunks = self.iterencode(o, _one_shot=True)
  File "/usr/lib/python3.7/json/encoder.py", line 257, in iterencode
    return _iterencode(o, 0)
  File "/home/user/.local/lib/python3.7/site-packages/mpld3/_display.py", line 139, in default
    return json.JSONEncoder.default(self, obj)
  File "/usr/lib/python3.7/json/encoder.py", line 179, in default
    raise TypeError(f'Object of type {o.__class__.__name__} '
TypeError: Object of type chain is not JSON serializable
2020-05-06 14:22:44,809 INFO: Microblog startup [in /home/user/Documents/Scripts/microblog/app/__init__.py:46]
2020-05-06 14:25:05,645 INFO: Microblog startup [in /home/user/Documents/Scripts/microblog/app/__init__.py:46]
2020-05-06 14:25:07,687 ERROR: Exception on /cpu [POST] [in /home/user/.local/lib/python3.7/site-packages/flask/app.py:1891]
Traceback (most recent call last):
  File "/home/user/.local/lib/python3.7/site-packages/flask/app.py", line 2446, in wsgi_app
    response = self.full_dispatch_request()
  File "/home/user/.local/lib/python3.7/site-packages/flask/app.py", line 1951, in full_dispatch_request
    rv = self.handle_user_exception(e)
  File "/home/user/.local/lib/python3.7/site-packages/flask/app.py", line 1820, in handle_user_exception
    reraise(exc_type, exc_value, tb)
  File "/home/user/.local/lib/python3.7/site-packages/flask/_compat.py", line 39, in reraise
    raise value
  File "/home/user/.local/lib/python3.7/site-packages/flask/app.py", line 1949, in full_dispatch_request
    rv = self.dispatch_request()
  File "/home/user/.local/lib/python3.7/site-packages/flask/app.py", line 1935, in dispatch_request
    return self.view_functions[rule.endpoint](**req.view_args)
  File "/home/user/.local/lib/python3.7/site-packages/flask_login/utils.py", line 261, in decorated_view
    return func(*args, **kwargs)
  File "/home/user/Documents/Scripts/microblog/app/routes.py", line 169, in cpu
    hour= time.strptime('%d %H:%M:%S')
TypeError: strptime() takes exactly 2 arguments (1 given)
2020-05-06 14:25:39,879 INFO: Microblog startup [in /home/user/Documents/Scripts/microblog/app/__init__.py:46]
2020-05-06 14:25:41,656 ERROR: Exception on /cpu [POST] [in /home/user/.local/lib/python3.7/site-packages/flask/app.py:1891]
Traceback (most recent call last):
  File "/home/user/.local/lib/python3.7/site-packages/flask/app.py", line 2446, in wsgi_app
    response = self.full_dispatch_request()
  File "/home/user/.local/lib/python3.7/site-packages/flask/app.py", line 1951, in full_dispatch_request
    rv = self.handle_user_exception(e)
  File "/home/user/.local/lib/python3.7/site-packages/flask/app.py", line 1820, in handle_user_exception
    reraise(exc_type, exc_value, tb)
  File "/home/user/.local/lib/python3.7/site-packages/flask/_compat.py", line 39, in reraise
    raise value
  File "/home/user/.local/lib/python3.7/site-packages/flask/app.py", line 1949, in full_dispatch_request
    rv = self.dispatch_request()
  File "/home/user/.local/lib/python3.7/site-packages/flask/app.py", line 1935, in dispatch_request
    return self.view_functions[rule.endpoint](**req.view_args)
  File "/home/user/.local/lib/python3.7/site-packages/flask_login/utils.py", line 261, in decorated_view
    return func(*args, **kwargs)
  File "/home/user/Documents/Scripts/microblog/app/routes.py", line 169, in cpu
    hour= time.strptime(time[1],'%d %H:%M:%S')
TypeError: 'datetime.datetime' object is not subscriptable
2020-05-06 14:30:49,571 INFO: Microblog startup [in /home/user/Documents/Scripts/microblog/app/__init__.py:46]
2020-05-06 14:30:51,501 ERROR: Exception on /cpu [POST] [in /home/user/.local/lib/python3.7/site-packages/flask/app.py:1891]
Traceback (most recent call last):
  File "/home/user/.local/lib/python3.7/site-packages/flask/app.py", line 2446, in wsgi_app
    response = self.full_dispatch_request()
  File "/home/user/.local/lib/python3.7/site-packages/flask/app.py", line 1951, in full_dispatch_request
    rv = self.handle_user_exception(e)
  File "/home/user/.local/lib/python3.7/site-packages/flask/app.py", line 1820, in handle_user_exception
    reraise(exc_type, exc_value, tb)
  File "/home/user/.local/lib/python3.7/site-packages/flask/_compat.py", line 39, in reraise
    raise value
  File "/home/user/.local/lib/python3.7/site-packages/flask/app.py", line 1949, in full_dispatch_request
    rv = self.dispatch_request()
  File "/home/user/.local/lib/python3.7/site-packages/flask/app.py", line 1935, in dispatch_request
    return self.view_functions[rule.endpoint](**req.view_args)
  File "/home/user/.local/lib/python3.7/site-packages/flask_login/utils.py", line 261, in decorated_view
    return func(*args, **kwargs)
  File "/home/user/Documents/Scripts/microblog/app/routes.py", line 168, in cpu
    for time, cpu in time_list, cpu_list:
ValueError: too many values to unpack (expected 2)
2020-05-06 14:31:26,339 INFO: Microblog startup [in /home/user/Documents/Scripts/microblog/app/__init__.py:46]
2020-05-06 14:31:28,189 ERROR: Exception on /cpu [POST] [in /home/user/.local/lib/python3.7/site-packages/flask/app.py:1891]
Traceback (most recent call last):
  File "/home/user/.local/lib/python3.7/site-packages/flask/app.py", line 2446, in wsgi_app
    response = self.full_dispatch_request()
  File "/home/user/.local/lib/python3.7/site-packages/flask/app.py", line 1951, in full_dispatch_request
    rv = self.handle_user_exception(e)
  File "/home/user/.local/lib/python3.7/site-packages/flask/app.py", line 1820, in handle_user_exception
    reraise(exc_type, exc_value, tb)
  File "/home/user/.local/lib/python3.7/site-packages/flask/_compat.py", line 39, in reraise
    raise value
  File "/home/user/.local/lib/python3.7/site-packages/flask/app.py", line 1949, in full_dispatch_request
    rv = self.dispatch_request()
  File "/home/user/.local/lib/python3.7/site-packages/flask/app.py", line 1935, in dispatch_request
    return self.view_functions[rule.endpoint](**req.view_args)
  File "/home/user/.local/lib/python3.7/site-packages/flask_login/utils.py", line 261, in decorated_view
    return func(*args, **kwargs)
  File "/home/user/Documents/Scripts/microblog/app/routes.py", line 168, in cpu
    for time, cpu in time_list, cpu_list:
ValueError: too many values to unpack (expected 2)
2020-05-06 14:33:02,519 INFO: Microblog startup [in /home/user/Documents/Scripts/microblog/app/__init__.py:46]
2020-05-06 14:33:25,332 INFO: Microblog startup [in /home/user/Documents/Scripts/microblog/app/__init__.py:46]
2020-05-06 14:33:55,071 INFO: Microblog startup [in /home/user/Documents/Scripts/microblog/app/__init__.py:46]
