2020-01-08 06:52:58,760 INFO: Microblog startup [in /home/user/Documents/Scripts/microblog/app/__init__.py:43]
2020-01-08 06:53:17,676 INFO: Microblog startup [in /home/user/Documents/Scripts/microblog/app/__init__.py:43]
2020-01-08 06:53:48,825 INFO: Microblog startup [in /home/user/Documents/Scripts/microblog/app/__init__.py:43]
2020-01-08 06:53:50,028 ERROR: Exception on /index [GET] [in /usr/lib/python3/dist-packages/flask/app.py:1761]
Traceback (most recent call last):
  File "/usr/lib/python3/dist-packages/flask/app.py", line 2292, in wsgi_app
    response = self.full_dispatch_request()
  File "/usr/lib/python3/dist-packages/flask/app.py", line 1815, in full_dispatch_request
    rv = self.handle_user_exception(e)
  File "/usr/lib/python3/dist-packages/flask/app.py", line 1718, in handle_user_exception
    reraise(exc_type, exc_value, tb)
  File "/usr/lib/python3/dist-packages/flask/_compat.py", line 35, in reraise
    raise value
  File "/usr/lib/python3/dist-packages/flask/app.py", line 1813, in full_dispatch_request
    rv = self.dispatch_request()
  File "/usr/lib/python3/dist-packages/flask/app.py", line 1799, in dispatch_request
    return self.view_functions[rule.endpoint](**req.view_args)
  File "/home/user/.local/lib/python3.7/site-packages/flask_login/utils.py", line 261, in decorated_view
    return func(*args, **kwargs)
  File "/home/user/Documents/Scripts/microblog/app/routes.py", line 26, in index
    {system}
TypeError: unhashable type: 'list'
2020-01-08 06:54:06,555 INFO: Microblog startup [in /home/user/Documents/Scripts/microblog/app/__init__.py:43]
2020-01-08 06:54:39,051 INFO: Microblog startup [in /home/user/Documents/Scripts/microblog/app/__init__.py:43]
2020-01-08 06:55:04,934 INFO: Microblog startup [in /home/user/Documents/Scripts/microblog/app/__init__.py:43]
2020-01-08 06:56:06,890 INFO: Microblog startup [in /home/user/Documents/Scripts/microblog/app/__init__.py:43]
2020-01-08 06:58:41,169 INFO: Microblog startup [in /home/user/Documents/Scripts/microblog/app/__init__.py:43]
2020-01-08 06:59:03,727 INFO: Microblog startup [in /home/user/Documents/Scripts/microblog/app/__init__.py:43]
2020-01-08 07:01:22,266 INFO: Microblog startup [in /home/user/Documents/Scripts/microblog/app/__init__.py:43]
2020-01-08 07:01:23,693 ERROR: Exception on /index [GET] [in /usr/lib/python3/dist-packages/flask/app.py:1761]
Traceback (most recent call last):
  File "/usr/lib/python3/dist-packages/flask/app.py", line 2292, in wsgi_app
    response = self.full_dispatch_request()
  File "/usr/lib/python3/dist-packages/flask/app.py", line 1815, in full_dispatch_request
    rv = self.handle_user_exception(e)
  File "/usr/lib/python3/dist-packages/flask/app.py", line 1718, in handle_user_exception
    reraise(exc_type, exc_value, tb)
  File "/usr/lib/python3/dist-packages/flask/_compat.py", line 35, in reraise
    raise value
  File "/usr/lib/python3/dist-packages/flask/app.py", line 1813, in full_dispatch_request
    rv = self.dispatch_request()
  File "/usr/lib/python3/dist-packages/flask/app.py", line 1799, in dispatch_request
    return self.view_functions[rule.endpoint](**req.view_args)
  File "/home/user/.local/lib/python3.7/site-packages/flask_login/utils.py", line 261, in decorated_view
    return func(*args, **kwargs)
  File "/home/user/Documents/Scripts/microblog/app/routes.py", line 24, in index
    system = System.query.getfirst()
AttributeError: 'BaseQuery' object has no attribute 'getfirst'
2020-01-08 07:03:31,831 INFO: Microblog startup [in /home/user/Documents/Scripts/microblog/app/__init__.py:43]
2020-01-08 07:03:35,389 ERROR: Exception on /index [GET] [in /usr/lib/python3/dist-packages/flask/app.py:1761]
Traceback (most recent call last):
  File "/usr/lib/python3/dist-packages/flask/app.py", line 2292, in wsgi_app
    response = self.full_dispatch_request()
  File "/usr/lib/python3/dist-packages/flask/app.py", line 1815, in full_dispatch_request
    rv = self.handle_user_exception(e)
  File "/usr/lib/python3/dist-packages/flask/app.py", line 1718, in handle_user_exception
    reraise(exc_type, exc_value, tb)
  File "/usr/lib/python3/dist-packages/flask/_compat.py", line 35, in reraise
    raise value
  File "/usr/lib/python3/dist-packages/flask/app.py", line 1813, in full_dispatch_request
    rv = self.dispatch_request()
  File "/usr/lib/python3/dist-packages/flask/app.py", line 1799, in dispatch_request
    return self.view_functions[rule.endpoint](**req.view_args)
  File "/home/user/.local/lib/python3.7/site-packages/flask_login/utils.py", line 261, in decorated_view
    return func(*args, **kwargs)
  File "/home/user/Documents/Scripts/microblog/app/routes.py", line 26, in index
    system = System.query.get()
TypeError: get() missing 1 required positional argument: 'ident'
2020-01-08 07:10:17,369 INFO: Microblog startup [in /home/user/Documents/Scripts/microblog/app/__init__.py:43]
2020-01-08 07:10:21,573 ERROR: Exception on /index [GET] [in /usr/lib/python3/dist-packages/flask/app.py:1761]
Traceback (most recent call last):
  File "/usr/lib/python3/dist-packages/flask/app.py", line 2292, in wsgi_app
    response = self.full_dispatch_request()
  File "/usr/lib/python3/dist-packages/flask/app.py", line 1815, in full_dispatch_request
    rv = self.handle_user_exception(e)
  File "/usr/lib/python3/dist-packages/flask/app.py", line 1718, in handle_user_exception
    reraise(exc_type, exc_value, tb)
  File "/usr/lib/python3/dist-packages/flask/_compat.py", line 35, in reraise
    raise value
  File "/usr/lib/python3/dist-packages/flask/app.py", line 1813, in full_dispatch_request
    rv = self.dispatch_request()
  File "/usr/lib/python3/dist-packages/flask/app.py", line 1799, in dispatch_request
    return self.view_functions[rule.endpoint](**req.view_args)
  File "/home/user/.local/lib/python3.7/site-packages/flask_login/utils.py", line 261, in decorated_view
    return func(*args, **kwargs)
  File "/home/user/Documents/Scripts/microblog/app/routes.py", line 26, in index
    systems.get(system)
AttributeError: 'list' object has no attribute 'get'
2020-01-08 07:10:46,196 INFO: Microblog startup [in /home/user/Documents/Scripts/microblog/app/__init__.py:43]
2020-01-08 07:10:48,061 ERROR: Exception on /index [GET] [in /usr/lib/python3/dist-packages/flask/app.py:1761]
Traceback (most recent call last):
  File "/usr/lib/python3/dist-packages/flask/app.py", line 2292, in wsgi_app
    response = self.full_dispatch_request()
  File "/usr/lib/python3/dist-packages/flask/app.py", line 1815, in full_dispatch_request
    rv = self.handle_user_exception(e)
  File "/usr/lib/python3/dist-packages/flask/app.py", line 1718, in handle_user_exception
    reraise(exc_type, exc_value, tb)
  File "/usr/lib/python3/dist-packages/flask/_compat.py", line 35, in reraise
    raise value
  File "/usr/lib/python3/dist-packages/flask/app.py", line 1813, in full_dispatch_request
    rv = self.dispatch_request()
  File "/usr/lib/python3/dist-packages/flask/app.py", line 1799, in dispatch_request
    return self.view_functions[rule.endpoint](**req.view_args)
  File "/home/user/.local/lib/python3.7/site-packages/flask_login/utils.py", line 261, in decorated_view
    return func(*args, **kwargs)
  File "/home/user/Documents/Scripts/microblog/app/routes.py", line 26, in index
    systems.query.get(system)
AttributeError: 'list' object has no attribute 'query'
2020-01-08 07:11:37,709 INFO: Microblog startup [in /home/user/Documents/Scripts/microblog/app/__init__.py:43]
