2020-05-16 15:03:51,133 ERROR: Exception on /user/roan [GET] [in /home/user/.local/lib/python3.7/site-packages/flask/app.py:1891]
Traceback (most recent call last):
  File "/home/user/.local/lib/python3.7/site-packages/flask/app.py", line 2446, in wsgi_app
    response = self.full_dispatch_request()
  File "/home/user/.local/lib/python3.7/site-packages/flask/app.py", line 1951, in full_dispatch_request
    rv = self.handle_user_exception(e)
  File "/home/user/.local/lib/python3.7/site-packages/flask/app.py", line 1820, in handle_user_exception
    reraise(exc_type, exc_value, tb)
  File "/home/user/.local/lib/python3.7/site-packages/flask/_compat.py", line 39, in reraise
    raise value
  File "/home/user/.local/lib/python3.7/site-packages/flask/app.py", line 1949, in full_dispatch_request
    rv = self.dispatch_request()
  File "/home/user/.local/lib/python3.7/site-packages/flask/app.py", line 1935, in dispatch_request
    return self.view_functions[rule.endpoint](**req.view_args)
  File "/home/user/.local/lib/python3.7/site-packages/flask_login/utils.py", line 261, in decorated_view
    return func(*args, **kwargs)
  File "/home/user/Documents/Scripts/microblog/app/routes.py", line 88, in user
    system1, system2 = uniqueList
ValueError: not enough values to unpack (expected 2, got 1)
2020-05-16 15:05:00,133 ERROR: Exception on /user/roan [GET] [in /home/user/.local/lib/python3.7/site-packages/flask/app.py:1891]
Traceback (most recent call last):
  File "/home/user/.local/lib/python3.7/site-packages/flask/app.py", line 2446, in wsgi_app
    response = self.full_dispatch_request()
  File "/home/user/.local/lib/python3.7/site-packages/flask/app.py", line 1951, in full_dispatch_request
    rv = self.handle_user_exception(e)
  File "/home/user/.local/lib/python3.7/site-packages/flask/app.py", line 1820, in handle_user_exception
    reraise(exc_type, exc_value, tb)
  File "/home/user/.local/lib/python3.7/site-packages/flask/_compat.py", line 39, in reraise
    raise value
  File "/home/user/.local/lib/python3.7/site-packages/flask/app.py", line 1949, in full_dispatch_request
    rv = self.dispatch_request()
  File "/home/user/.local/lib/python3.7/site-packages/flask/app.py", line 1935, in dispatch_request
    return self.view_functions[rule.endpoint](**req.view_args)
  File "/home/user/.local/lib/python3.7/site-packages/flask_login/utils.py", line 261, in decorated_view
    return func(*args, **kwargs)
  File "/home/user/Documents/Scripts/microblog/app/routes.py", line 88, in user
    system1, system2 = uniqueList
ValueError: not enough values to unpack (expected 2, got 1)
2020-05-16 15:05:01,041 ERROR: Exception on /user/roan [GET] [in /home/user/.local/lib/python3.7/site-packages/flask/app.py:1891]
Traceback (most recent call last):
  File "/home/user/.local/lib/python3.7/site-packages/flask/app.py", line 2446, in wsgi_app
    response = self.full_dispatch_request()
  File "/home/user/.local/lib/python3.7/site-packages/flask/app.py", line 1951, in full_dispatch_request
    rv = self.handle_user_exception(e)
  File "/home/user/.local/lib/python3.7/site-packages/flask/app.py", line 1820, in handle_user_exception
    reraise(exc_type, exc_value, tb)
  File "/home/user/.local/lib/python3.7/site-packages/flask/_compat.py", line 39, in reraise
    raise value
  File "/home/user/.local/lib/python3.7/site-packages/flask/app.py", line 1949, in full_dispatch_request
    rv = self.dispatch_request()
  File "/home/user/.local/lib/python3.7/site-packages/flask/app.py", line 1935, in dispatch_request
    return self.view_functions[rule.endpoint](**req.view_args)
  File "/home/user/.local/lib/python3.7/site-packages/flask_login/utils.py", line 261, in decorated_view
    return func(*args, **kwargs)
  File "/home/user/Documents/Scripts/microblog/app/routes.py", line 88, in user
    system1, system2 = uniqueList
ValueError: not enough values to unpack (expected 2, got 1)
2020-05-17 12:04:22,110 INFO: MicroMonitor startup [in /home/user/Documents/Scripts/microblog/app/__init__.py:46]
2020-05-17 12:06:28,079 INFO: MicroMonitor startup [in /home/user/Documents/Scripts/microblog/app/__init__.py:46]
2020-05-17 12:08:21,216 INFO: MicroMonitor startup [in /home/user/Documents/Scripts/microblog/app/__init__.py:46]
2020-05-17 12:23:49,595 INFO: MicroMonitor startup [in /home/user/Documents/Scripts/micromonitor/app/__init__.py:46]
