2020-05-02 17:29:23,175 ERROR: Exception on /disk [GET] [in /home/user/.local/lib/python3.7/site-packages/flask/app.py:1891]
Traceback (most recent call last):
  File "/home/user/.local/lib/python3.7/site-packages/flask/app.py", line 2446, in wsgi_app
    response = self.full_dispatch_request()
  File "/home/user/.local/lib/python3.7/site-packages/flask/app.py", line 1951, in full_dispatch_request
    rv = self.handle_user_exception(e)
  File "/home/user/.local/lib/python3.7/site-packages/flask/app.py", line 1820, in handle_user_exception
    reraise(exc_type, exc_value, tb)
  File "/home/user/.local/lib/python3.7/site-packages/flask/_compat.py", line 39, in reraise
    raise value
  File "/home/user/.local/lib/python3.7/site-packages/flask/app.py", line 1949, in full_dispatch_request
    rv = self.dispatch_request()
  File "/home/user/.local/lib/python3.7/site-packages/flask/app.py", line 1935, in dispatch_request
    return self.view_functions[rule.endpoint](**req.view_args)
  File "/home/user/Documents/Scripts/microblog/app/routes.py", line 222, in disk
    return render_template('disk.html', plot=html_text)
  File "/home/user/.local/lib/python3.7/site-packages/flask/templating.py", line 140, in render_template
    ctx.app,
  File "/home/user/.local/lib/python3.7/site-packages/flask/templating.py", line 120, in _render
    rv = template.render(context)
  File "/home/user/.local/lib/python3.7/site-packages/jinja2/asyncsupport.py", line 76, in render
    return original_render(self, *args, **kwargs)
  File "/home/user/.local/lib/python3.7/site-packages/jinja2/environment.py", line 1008, in render
    return self.environment.handle_exception(exc_info, True)
  File "/home/user/.local/lib/python3.7/site-packages/jinja2/environment.py", line 780, in handle_exception
    reraise(exc_type, exc_value, tb)
  File "/home/user/.local/lib/python3.7/site-packages/jinja2/_compat.py", line 37, in reraise
    raise value.with_traceback(tb)
  File "/home/user/Documents/Scripts/microblog/app/templates/disk.html", line 1, in top-level template code
    {% extends "base.html" %}
  File "/home/user/.local/lib/python3.7/site-packages/jinja2/environment.py", line 1005, in render
    return concat(self.root_render_func(self.new_context(vars)))
  File "/home/user/Documents/Scripts/microblog/app/templates/disk.html", line 14, in root
    </select>
  File "/home/user/Documents/Scripts/microblog/app/templates/base.html", line 14, in root
    <a class="nav-link dropdown-toggle" data-toggle="dropdown" role="button" aria-haspopup="true" aria-expanded="false" href="{{ url_for('index') }}">
  File "/home/user/.local/lib/python3.7/site-packages/flask_bootstrap/templates/bootstrap/base.html", line 10, in root
    <meta name="viewport" content="width=device-width, initial-scale=1.0">
  File "/home/user/.local/lib/python3.7/site-packages/flask_bootstrap/templates/bootstrap/base.html", line 20, in block_doc
    {% block body -%}
  File "/home/user/.local/lib/python3.7/site-packages/flask_bootstrap/templates/bootstrap/base.html", line 39, in block_html
  File "/home/user/.local/lib/python3.7/site-packages/flask_bootstrap/templates/bootstrap/base.html", line 92, in block_body
  File "/home/user/Documents/Scripts/microblog/app/templates/disk.html", line 28, in block_content
  File "/home/user/.local/lib/python3.7/site-packages/jinja2/environment.py", line 411, in getitem
    return obj[argument]
jinja2.exceptions.UndefinedError: 'systems' is undefined
2020-05-02 17:29:47,792 INFO: Microblog startup [in /home/user/Documents/Scripts/microblog/app/__init__.py:46]
2020-05-02 17:33:19,264 INFO: Microblog startup [in /home/user/Documents/Scripts/microblog/app/__init__.py:46]
2020-05-02 17:33:23,398 ERROR: Exception on /disk [GET] [in /home/user/.local/lib/python3.7/site-packages/flask/app.py:1891]
Traceback (most recent call last):
  File "/home/user/.local/lib/python3.7/site-packages/flask/app.py", line 2446, in wsgi_app
    response = self.full_dispatch_request()
  File "/home/user/.local/lib/python3.7/site-packages/flask/app.py", line 1951, in full_dispatch_request
    rv = self.handle_user_exception(e)
  File "/home/user/.local/lib/python3.7/site-packages/flask/app.py", line 1820, in handle_user_exception
    reraise(exc_type, exc_value, tb)
  File "/home/user/.local/lib/python3.7/site-packages/flask/_compat.py", line 39, in reraise
    raise value
  File "/home/user/.local/lib/python3.7/site-packages/flask/app.py", line 1949, in full_dispatch_request
    rv = self.dispatch_request()
  File "/home/user/.local/lib/python3.7/site-packages/flask/app.py", line 1935, in dispatch_request
    return self.view_functions[rule.endpoint](**req.view_args)
  File "/home/user/Documents/Scripts/microblog/app/routes.py", line 203, in disk
    query = session.query(System.disk_free).filter_by(system_id='ubuntu').last()
AttributeError: 'BaseQuery' object has no attribute 'last'
2020-05-02 17:35:22,326 INFO: Microblog startup [in /home/user/Documents/Scripts/microblog/app/__init__.py:46]
2020-05-02 17:35:23,536 ERROR: Exception on /disk [GET] [in /home/user/.local/lib/python3.7/site-packages/flask/app.py:1891]
Traceback (most recent call last):
  File "/home/user/.local/lib/python3.7/site-packages/flask/app.py", line 2446, in wsgi_app
    response = self.full_dispatch_request()
  File "/home/user/.local/lib/python3.7/site-packages/flask/app.py", line 1951, in full_dispatch_request
    rv = self.handle_user_exception(e)
  File "/home/user/.local/lib/python3.7/site-packages/flask/app.py", line 1820, in handle_user_exception
    reraise(exc_type, exc_value, tb)
  File "/home/user/.local/lib/python3.7/site-packages/flask/_compat.py", line 39, in reraise
    raise value
  File "/home/user/.local/lib/python3.7/site-packages/flask/app.py", line 1949, in full_dispatch_request
    rv = self.dispatch_request()
  File "/home/user/.local/lib/python3.7/site-packages/flask/app.py", line 1935, in dispatch_request
    return self.view_functions[rule.endpoint](**req.view_args)
  File "/home/user/Documents/Scripts/microblog/app/routes.py", line 203, in disk
    query = session.query(System.disk_free).filter_by(system_id='ubuntu').order_by(System.timestamp.desc).first()
  File "<string>", line 2, in order_by
  File "/home/user/.local/lib/python3.7/site-packages/sqlalchemy/orm/base.py", line 220, in generate
    fn(self, *args[1:], **kw)
  File "/home/user/.local/lib/python3.7/site-packages/sqlalchemy/orm/query.py", line 1850, in order_by
    criterion = self._adapt_col_list(criterion)
  File "/home/user/.local/lib/python3.7/site-packages/sqlalchemy/orm/query.py", line 312, in _adapt_col_list
    for o in cols
  File "/home/user/.local/lib/python3.7/site-packages/sqlalchemy/orm/query.py", line 312, in <listcomp>
    for o in cols
  File "/home/user/.local/lib/python3.7/site-packages/sqlalchemy/sql/elements.py", line 4536, in _literal_as_label_reference
    return _literal_as_text(element)
  File "/home/user/.local/lib/python3.7/site-packages/sqlalchemy/sql/elements.py", line 4579, in _literal_as_text
    return _literal_as(element, _no_text_coercion)
  File "/home/user/.local/lib/python3.7/site-packages/sqlalchemy/sql/elements.py", line 4571, in _literal_as
    "instead" % type(element)
sqlalchemy.exc.ArgumentError: SQL expression object expected, got object of type <class 'method'> instead
2020-05-02 17:36:44,839 INFO: Microblog startup [in /home/user/Documents/Scripts/microblog/app/__init__.py:46]
