2020-05-02 16:44:03,060 ERROR: Exception on /cpu [GET] [in /home/user/.local/lib/python3.7/site-packages/flask/app.py:1891]
Traceback (most recent call last):
  File "/home/user/.local/lib/python3.7/site-packages/flask/app.py", line 2446, in wsgi_app
    response = self.full_dispatch_request()
  File "/home/user/.local/lib/python3.7/site-packages/flask/app.py", line 1951, in full_dispatch_request
    rv = self.handle_user_exception(e)
  File "/home/user/.local/lib/python3.7/site-packages/flask/app.py", line 1820, in handle_user_exception
    reraise(exc_type, exc_value, tb)
  File "/home/user/.local/lib/python3.7/site-packages/flask/_compat.py", line 39, in reraise
    raise value
  File "/home/user/.local/lib/python3.7/site-packages/flask/app.py", line 1949, in full_dispatch_request
    rv = self.dispatch_request()
  File "/home/user/.local/lib/python3.7/site-packages/flask/app.py", line 1935, in dispatch_request
    return self.view_functions[rule.endpoint](**req.view_args)
  File "/home/user/.local/lib/python3.7/site-packages/flask_login/utils.py", line 261, in decorated_view
    return func(*args, **kwargs)
  File "/home/user/Documents/Scripts/microblog/app/routes.py", line 191, in cpu
    return render_template('cpu.html', plot=html_text, systems=uniqueList)
  File "/home/user/.local/lib/python3.7/site-packages/flask/templating.py", line 140, in render_template
    ctx.app,
  File "/home/user/.local/lib/python3.7/site-packages/flask/templating.py", line 120, in _render
    rv = template.render(context)
  File "/home/user/.local/lib/python3.7/site-packages/jinja2/asyncsupport.py", line 76, in render
    return original_render(self, *args, **kwargs)
  File "/home/user/.local/lib/python3.7/site-packages/jinja2/environment.py", line 1008, in render
    return self.environment.handle_exception(exc_info, True)
  File "/home/user/.local/lib/python3.7/site-packages/jinja2/environment.py", line 780, in handle_exception
    reraise(exc_type, exc_value, tb)
  File "/home/user/.local/lib/python3.7/site-packages/jinja2/_compat.py", line 37, in reraise
    raise value.with_traceback(tb)
  File "/home/user/Documents/Scripts/microblog/app/templates/cpu.html", line 1, in top-level template code
    {% extends "base.html" %}
  File "/home/user/.local/lib/python3.7/site-packages/jinja2/environment.py", line 1005, in render
    return concat(self.root_render_func(self.new_context(vars)))
  File "/home/user/Documents/Scripts/microblog/app/templates/cpu.html", line 14, in root
    </select>
  File "/home/user/Documents/Scripts/microblog/app/templates/base.html", line 14, in root
    <a class="nav-link dropdown-toggle" href="#" id="navbarDropdownMenuLink" role="button" data-toggle="dropdown" aria-haspopup="true" aria-expanded="false">
  File "/home/user/.local/lib/python3.7/site-packages/flask_bootstrap/templates/bootstrap/base.html", line 10, in root
    <meta name="viewport" content="width=device-width, initial-scale=1.0">
  File "/home/user/.local/lib/python3.7/site-packages/flask_bootstrap/templates/bootstrap/base.html", line 20, in block_doc
    {% block body -%}
  File "/home/user/.local/lib/python3.7/site-packages/flask_bootstrap/templates/bootstrap/base.html", line 39, in block_html
  File "/home/user/.local/lib/python3.7/site-packages/flask_bootstrap/templates/bootstrap/base.html", line 92, in block_body
  File "/home/user/Documents/Scripts/microblog/app/templates/cpu.html", line 26, in block_content
  File "/home/user/.local/lib/python3.7/site-packages/jinja2/runtime.py", line 262, in call
    return __obj(*args, **kwargs)
  File "/home/user/.local/lib/python3.7/site-packages/flask/helpers.py", line 370, in url_for
    return appctx.app.handle_url_build_error(error, endpoint, values)
  File "/home/user/.local/lib/python3.7/site-packages/flask/app.py", line 2215, in handle_url_build_error
    reraise(exc_type, exc_value, tb)
  File "/home/user/.local/lib/python3.7/site-packages/flask/_compat.py", line 39, in reraise
    raise value
  File "/home/user/.local/lib/python3.7/site-packages/flask/helpers.py", line 358, in url_for
    endpoint, values, method=method, force_external=external
  File "/home/user/.local/lib/python3.7/site-packages/werkzeug/routing.py", line 2020, in build
    raise BuildError(endpoint, values, method, self)
werkzeug.routing.BuildError: Could not build url for endpoint 'monitoring'. Did you mean 'login' instead?
2020-05-02 16:46:11,051 INFO: Microblog startup [in /home/user/Documents/Scripts/microblog/app/__init__.py:46]
2020-05-02 16:51:19,814 INFO: Microblog startup [in /home/user/Documents/Scripts/microblog/app/__init__.py:46]
2020-05-02 16:54:14,517 INFO: Microblog startup [in /home/user/Documents/Scripts/microblog/app/__init__.py:46]
2020-05-02 16:55:06,158 INFO: Microblog startup [in /home/user/Documents/Scripts/microblog/app/__init__.py:46]
2020-05-02 16:57:09,552 INFO: Microblog startup [in /home/user/Documents/Scripts/microblog/app/__init__.py:46]
2020-05-02 16:58:22,994 INFO: Microblog startup [in /home/user/Documents/Scripts/microblog/app/__init__.py:46]
2020-05-02 17:01:12,782 INFO: Microblog startup [in /home/user/Documents/Scripts/microblog/app/__init__.py:46]
2020-05-02 17:01:52,283 INFO: Microblog startup [in /home/user/Documents/Scripts/microblog/app/__init__.py:46]
2020-05-02 17:02:27,354 INFO: Microblog startup [in /home/user/Documents/Scripts/microblog/app/__init__.py:46]
2020-05-02 17:02:59,361 INFO: Microblog startup [in /home/user/Documents/Scripts/microblog/app/__init__.py:46]
2020-05-02 17:08:00,104 INFO: Microblog startup [in /home/user/Documents/Scripts/microblog/app/__init__.py:46]
2020-05-02 17:09:35,062 INFO: Microblog startup [in /home/user/Documents/Scripts/microblog/app/__init__.py:46]
2020-05-02 17:16:15,890 INFO: Microblog startup [in /home/user/Documents/Scripts/microblog/app/__init__.py:46]
