2020-05-02 14:56:34,797 ERROR: Exception on /monitoring [GET] [in /home/user/.local/lib/python3.7/site-packages/flask/app.py:1891]
Traceback (most recent call last):
  File "/home/user/.local/lib/python3.7/site-packages/flask/app.py", line 2446, in wsgi_app
    response = self.full_dispatch_request()
  File "/home/user/.local/lib/python3.7/site-packages/flask/app.py", line 1951, in full_dispatch_request
    rv = self.handle_user_exception(e)
  File "/home/user/.local/lib/python3.7/site-packages/flask/app.py", line 1820, in handle_user_exception
    reraise(exc_type, exc_value, tb)
  File "/home/user/.local/lib/python3.7/site-packages/flask/_compat.py", line 39, in reraise
    raise value
  File "/home/user/.local/lib/python3.7/site-packages/flask/app.py", line 1949, in full_dispatch_request
    rv = self.dispatch_request()
  File "/home/user/.local/lib/python3.7/site-packages/flask/app.py", line 1935, in dispatch_request
    return self.view_functions[rule.endpoint](**req.view_args)
  File "/home/user/.local/lib/python3.7/site-packages/flask_login/utils.py", line 261, in decorated_view
    return func(*args, **kwargs)
  File "/home/user/Documents/Scripts/microblog/app/routes.py", line 197, in monitoring
    html_text = mpld3.fig_to_html(figure)
  File "/home/user/.local/lib/python3.7/site-packages/mpld3/_display.py", line 240, in fig_to_html
    Exporter(renderer, close_mpl=False, **kwargs).run(fig)
  File "/home/user/.local/lib/python3.7/site-packages/mpld3/mplexporter/exporter.py", line 47, in run
    fig.savefig(io.BytesIO(), format='png', dpi=fig.dpi)
  File "/home/user/.local/lib/python3.7/site-packages/matplotlib/figure.py", line 2180, in savefig
    self.canvas.print_figure(fname, **kwargs)
  File "/home/user/.local/lib/python3.7/site-packages/matplotlib/backend_bases.py", line 2089, in print_figure
    **kwargs)
  File "/home/user/.local/lib/python3.7/site-packages/matplotlib/backends/backend_gtk3agg.py", line 82, in print_png
    return agg.print_png(filename, *args, **kwargs)
  File "/home/user/.local/lib/python3.7/site-packages/matplotlib/backends/backend_agg.py", line 527, in print_png
    FigureCanvasAgg.draw(self)
  File "/home/user/.local/lib/python3.7/site-packages/matplotlib/backends/backend_agg.py", line 388, in draw
    self.figure.draw(self.renderer)
  File "/home/user/.local/lib/python3.7/site-packages/matplotlib/artist.py", line 38, in draw_wrapper
    return draw(artist, renderer, *args, **kwargs)
  File "/home/user/.local/lib/python3.7/site-packages/matplotlib/figure.py", line 1709, in draw
    renderer, self, artists, self.suppressComposite)
  File "/home/user/.local/lib/python3.7/site-packages/matplotlib/image.py", line 135, in _draw_list_compositing_images
    a.draw(renderer)
  File "/home/user/.local/lib/python3.7/site-packages/matplotlib/artist.py", line 38, in draw_wrapper
    return draw(artist, renderer, *args, **kwargs)
  File "/home/user/.local/lib/python3.7/site-packages/matplotlib/axes/_base.py", line 2647, in draw
    mimage._draw_list_compositing_images(renderer, self, artists)
  File "/home/user/.local/lib/python3.7/site-packages/matplotlib/image.py", line 135, in _draw_list_compositing_images
    a.draw(renderer)
  File "/home/user/.local/lib/python3.7/site-packages/matplotlib/artist.py", line 38, in draw_wrapper
    return draw(artist, renderer, *args, **kwargs)
  File "/home/user/.local/lib/python3.7/site-packages/matplotlib/axis.py", line 1203, in draw
    ticks_to_draw = self._update_ticks()
  File "/home/user/.local/lib/python3.7/site-packages/matplotlib/axis.py", line 1079, in _update_ticks
    major_locs = self.get_majorticklocs()
  File "/home/user/.local/lib/python3.7/site-packages/matplotlib/axis.py", line 1324, in get_majorticklocs
    return self.major.locator()
  File "/home/user/.local/lib/python3.7/site-packages/matplotlib/dates.py", line 1428, in __call__
    self.refresh()
  File "/home/user/.local/lib/python3.7/site-packages/matplotlib/dates.py", line 1448, in refresh
    dmin, dmax = self.viewlim_to_dt()
  File "/home/user/.local/lib/python3.7/site-packages/matplotlib/dates.py", line 1199, in viewlim_to_dt
    .format(vmin))
ValueError: view limit minimum 0.0 is less than 1 and is an invalid Matplotlib date value. This often happens if you pass a non-datetime value to an axis that has datetime units
2020-05-02 14:56:48,329 INFO: Microblog startup [in /home/user/Documents/Scripts/microblog/app/__init__.py:46]
2020-05-02 14:59:22,803 INFO: Microblog startup [in /home/user/Documents/Scripts/microblog/app/__init__.py:46]
2020-05-02 15:00:13,062 INFO: Microblog startup [in /home/user/Documents/Scripts/microblog/app/__init__.py:46]
2020-05-02 15:01:04,279 INFO: Microblog startup [in /home/user/Documents/Scripts/microblog/app/__init__.py:46]
2020-05-02 15:01:29,898 INFO: Microblog startup [in /home/user/Documents/Scripts/microblog/app/__init__.py:46]
2020-05-02 15:08:00,498 INFO: Microblog startup [in /home/user/Documents/Scripts/microblog/app/__init__.py:46]
2020-05-02 15:09:36,699 INFO: Microblog startup [in /home/user/Documents/Scripts/microblog/app/__init__.py:46]
2020-05-02 15:22:57,594 INFO: Microblog startup [in /home/user/Documents/Scripts/microblog/app/__init__.py:46]
2020-05-02 15:23:21,222 INFO: Microblog startup [in /home/user/Documents/Scripts/microblog/app/__init__.py:46]
2020-05-02 15:24:38,479 INFO: Microblog startup [in /home/user/Documents/Scripts/microblog/app/__init__.py:46]
2020-05-02 15:26:37,653 INFO: Microblog startup [in /home/user/Documents/Scripts/microblog/app/__init__.py:46]
2020-05-02 15:35:55,089 INFO: Microblog startup [in /home/user/Documents/Scripts/microblog/app/__init__.py:46]
2020-05-02 15:37:57,504 INFO: Microblog startup [in /home/user/Documents/Scripts/microblog/app/__init__.py:46]
2020-05-02 15:38:00,339 ERROR: Exception on /monitoring [GET] [in /home/user/.local/lib/python3.7/site-packages/flask/app.py:1891]
Traceback (most recent call last):
  File "/home/user/.local/lib/python3.7/site-packages/flask/app.py", line 2446, in wsgi_app
    response = self.full_dispatch_request()
  File "/home/user/.local/lib/python3.7/site-packages/flask/app.py", line 1951, in full_dispatch_request
    rv = self.handle_user_exception(e)
  File "/home/user/.local/lib/python3.7/site-packages/flask/app.py", line 1820, in handle_user_exception
    reraise(exc_type, exc_value, tb)
  File "/home/user/.local/lib/python3.7/site-packages/flask/_compat.py", line 39, in reraise
    raise value
  File "/home/user/.local/lib/python3.7/site-packages/flask/app.py", line 1949, in full_dispatch_request
    rv = self.dispatch_request()
  File "/home/user/.local/lib/python3.7/site-packages/flask/app.py", line 1935, in dispatch_request
    return self.view_functions[rule.endpoint](**req.view_args)
  File "/home/user/.local/lib/python3.7/site-packages/flask_login/utils.py", line 261, in decorated_view
    return func(*args, **kwargs)
  File "/home/user/Documents/Scripts/microblog/app/routes.py", line 191, in monitoring
    return render_template('cpu.html', plot=html_text, systems=uniqueList)
  File "/home/user/.local/lib/python3.7/site-packages/flask/templating.py", line 140, in render_template
    ctx.app,
  File "/home/user/.local/lib/python3.7/site-packages/flask/templating.py", line 120, in _render
    rv = template.render(context)
  File "/home/user/.local/lib/python3.7/site-packages/jinja2/asyncsupport.py", line 76, in render
    return original_render(self, *args, **kwargs)
  File "/home/user/.local/lib/python3.7/site-packages/jinja2/environment.py", line 1008, in render
    return self.environment.handle_exception(exc_info, True)
  File "/home/user/.local/lib/python3.7/site-packages/jinja2/environment.py", line 780, in handle_exception
    reraise(exc_type, exc_value, tb)
  File "/home/user/.local/lib/python3.7/site-packages/jinja2/_compat.py", line 37, in reraise
    raise value.with_traceback(tb)
  File "/home/user/Documents/Scripts/microblog/app/templates/cpu.html", line 1, in top-level template code
    {% extends "base.html" %}
  File "/home/user/.local/lib/python3.7/site-packages/jinja2/environment.py", line 1005, in render
    return concat(self.root_render_func(self.new_context(vars)))
  File "/home/user/Documents/Scripts/microblog/app/templates/cpu.html", line 14, in root
    </select>
  File "/home/user/Documents/Scripts/microblog/app/templates/base.html", line 14, in root
    <span class="icon-bar"></span>
  File "/home/user/.local/lib/python3.7/site-packages/flask_bootstrap/templates/bootstrap/base.html", line 10, in root
    <meta name="viewport" content="width=device-width, initial-scale=1.0">
  File "/home/user/.local/lib/python3.7/site-packages/flask_bootstrap/templates/bootstrap/base.html", line 20, in block_doc
    {% block body -%}
  File "/home/user/.local/lib/python3.7/site-packages/flask_bootstrap/templates/bootstrap/base.html", line 39, in block_html
  File "/home/user/.local/lib/python3.7/site-packages/flask_bootstrap/templates/bootstrap/base.html", line 92, in block_body
  File "/home/user/Documents/Scripts/microblog/app/templates/cpu.html", line 26, in block_content
  File "/home/user/.local/lib/python3.7/site-packages/jinja2/runtime.py", line 262, in call
    return __obj(*args, **kwargs)
  File "/home/user/.local/lib/python3.7/site-packages/flask/helpers.py", line 370, in url_for
    return appctx.app.handle_url_build_error(error, endpoint, values)
  File "/home/user/.local/lib/python3.7/site-packages/flask/app.py", line 2215, in handle_url_build_error
    reraise(exc_type, exc_value, tb)
  File "/home/user/.local/lib/python3.7/site-packages/flask/_compat.py", line 39, in reraise
    raise value
  File "/home/user/.local/lib/python3.7/site-packages/flask/helpers.py", line 358, in url_for
    endpoint, values, method=method, force_external=external
  File "/home/user/.local/lib/python3.7/site-packages/werkzeug/routing.py", line 2020, in build
    raise BuildError(endpoint, values, method, self)
werkzeug.routing.BuildError: Could not build url for endpoint '/monitoring'. Did you mean 'monitoring' instead?
2020-05-02 15:38:13,410 INFO: Microblog startup [in /home/user/Documents/Scripts/microblog/app/__init__.py:46]
