2020-05-02 17:36:45,835 ERROR: Exception on /disk [GET] [in /home/user/.local/lib/python3.7/site-packages/flask/app.py:1891]
Traceback (most recent call last):
  File "/home/user/.local/lib/python3.7/site-packages/sqlalchemy/sql/compiler.py", line 776, in visit_textual_label_reference
    col = with_cols[element.element]
KeyError: 'system_timestamp'

During handling of the above exception, another exception occurred:

Traceback (most recent call last):
  File "/home/user/.local/lib/python3.7/site-packages/flask/app.py", line 2446, in wsgi_app
    response = self.full_dispatch_request()
  File "/home/user/.local/lib/python3.7/site-packages/flask/app.py", line 1951, in full_dispatch_request
    rv = self.handle_user_exception(e)
  File "/home/user/.local/lib/python3.7/site-packages/flask/app.py", line 1820, in handle_user_exception
    reraise(exc_type, exc_value, tb)
  File "/home/user/.local/lib/python3.7/site-packages/flask/_compat.py", line 39, in reraise
    raise value
  File "/home/user/.local/lib/python3.7/site-packages/flask/app.py", line 1949, in full_dispatch_request
    rv = self.dispatch_request()
  File "/home/user/.local/lib/python3.7/site-packages/flask/app.py", line 1935, in dispatch_request
    return self.view_functions[rule.endpoint](**req.view_args)
  File "/home/user/Documents/Scripts/microblog/app/routes.py", line 203, in disk
    query = session.query(System.disk_free).filter_by(system_id='ubuntu').order_by('system_timestamp').first()
  File "/home/user/.local/lib/python3.7/site-packages/sqlalchemy/orm/query.py", line 3265, in first
    ret = list(self[0:1])
  File "/home/user/.local/lib/python3.7/site-packages/sqlalchemy/orm/query.py", line 3043, in __getitem__
    return list(res)
  File "/home/user/.local/lib/python3.7/site-packages/sqlalchemy/orm/query.py", line 3367, in __iter__
    return self._execute_and_instances(context)
  File "/home/user/.local/lib/python3.7/site-packages/sqlalchemy/orm/query.py", line 3392, in _execute_and_instances
    result = conn.execute(querycontext.statement, self._params)
  File "/home/user/.local/lib/python3.7/site-packages/sqlalchemy/engine/base.py", line 982, in execute
    return meth(self, multiparams, params)
  File "/home/user/.local/lib/python3.7/site-packages/sqlalchemy/sql/elements.py", line 287, in _execute_on_connection
    return connection._execute_clauseelement(self, multiparams, params)
  File "/home/user/.local/lib/python3.7/site-packages/sqlalchemy/engine/base.py", line 1092, in _execute_clauseelement
    else None,
  File "<string>", line 1, in <lambda>
  File "/home/user/.local/lib/python3.7/site-packages/sqlalchemy/sql/elements.py", line 462, in compile
    return self._compiler(dialect, bind=bind, **kw)
  File "/home/user/.local/lib/python3.7/site-packages/sqlalchemy/sql/elements.py", line 468, in _compiler
    return dialect.statement_compiler(dialect, self, **kw)
  File "/home/user/.local/lib/python3.7/site-packages/sqlalchemy/sql/compiler.py", line 571, in __init__
    Compiled.__init__(self, dialect, statement, **kwargs)
  File "/home/user/.local/lib/python3.7/site-packages/sqlalchemy/sql/compiler.py", line 319, in __init__
    self.string = self.process(self.statement, **compile_kwargs)
  File "/home/user/.local/lib/python3.7/site-packages/sqlalchemy/sql/compiler.py", line 350, in process
    return obj._compiler_dispatch(self, **kwargs)
  File "/home/user/.local/lib/python3.7/site-packages/sqlalchemy/sql/visitors.py", line 92, in _compiler_dispatch
    return meth(self, **kw)
  File "/home/user/.local/lib/python3.7/site-packages/sqlalchemy/sql/compiler.py", line 2140, in visit_select
    text, select, inner_columns, froms, byfrom, kwargs
  File "/home/user/.local/lib/python3.7/site-packages/sqlalchemy/sql/compiler.py", line 2252, in _compose_select_body
    text += self.order_by_clause(select, **kwargs)
  File "/home/user/.local/lib/python3.7/site-packages/sqlalchemy/sql/compiler.py", line 2311, in order_by_clause
    order_by = select._order_by_clause._compiler_dispatch(self, **kw)
  File "/home/user/.local/lib/python3.7/site-packages/sqlalchemy/sql/visitors.py", line 92, in _compiler_dispatch
    return meth(self, **kw)
  File "/home/user/.local/lib/python3.7/site-packages/sqlalchemy/sql/compiler.py", line 983, in visit_clauselist
    c._compiler_dispatch(self, **kw) for c in clauselist.clauses
  File "/home/user/.local/lib/python3.7/site-packages/sqlalchemy/sql/compiler.py", line 981, in <genexpr>
    s
  File "/home/user/.local/lib/python3.7/site-packages/sqlalchemy/sql/compiler.py", line 983, in <genexpr>
    c._compiler_dispatch(self, **kw) for c in clauselist.clauses
  File "/home/user/.local/lib/python3.7/site-packages/sqlalchemy/sql/visitors.py", line 92, in _compiler_dispatch
    return meth(self, **kw)
  File "/home/user/.local/lib/python3.7/site-packages/sqlalchemy/sql/compiler.py", line 781, in visit_textual_label_reference
    "Can't resolve label reference for ORDER BY / "
  File "/home/user/.local/lib/python3.7/site-packages/sqlalchemy/sql/elements.py", line 4609, in _no_text_coercion
    "extra": "%s " % extra if extra else "",
sqlalchemy.exc.CompileError: Can't resolve label reference for ORDER BY / GROUP BY / DISTINCT etc. Textual SQL expression 'system_timestamp' should be explicitly declared as text('system_timestamp')
2020-05-02 17:37:44,353 INFO: Microblog startup [in /home/user/Documents/Scripts/microblog/app/__init__.py:46]
2020-05-02 17:37:45,423 ERROR: Exception on /disk [GET] [in /home/user/.local/lib/python3.7/site-packages/flask/app.py:1891]
Traceback (most recent call last):
  File "/home/user/.local/lib/python3.7/site-packages/flask/app.py", line 2446, in wsgi_app
    response = self.full_dispatch_request()
  File "/home/user/.local/lib/python3.7/site-packages/flask/app.py", line 1951, in full_dispatch_request
    rv = self.handle_user_exception(e)
  File "/home/user/.local/lib/python3.7/site-packages/flask/app.py", line 1820, in handle_user_exception
    reraise(exc_type, exc_value, tb)
  File "/home/user/.local/lib/python3.7/site-packages/flask/_compat.py", line 39, in reraise
    raise value
  File "/home/user/.local/lib/python3.7/site-packages/flask/app.py", line 1949, in full_dispatch_request
    rv = self.dispatch_request()
  File "/home/user/.local/lib/python3.7/site-packages/flask/app.py", line 1935, in dispatch_request
    return self.view_functions[rule.endpoint](**req.view_args)
  File "/home/user/Documents/Scripts/microblog/app/routes.py", line 219, in disk
    shadow=True, startangle=90)
  File "/home/user/.local/lib/python3.7/site-packages/matplotlib/__init__.py", line 1599, in inner
    return func(ax, *map(sanitize_sequence, args), **kwargs)
  File "/home/user/.local/lib/python3.7/site-packages/matplotlib/axes/_axes.py", line 2982, in pie
    raise ValueError("'label' must be of length 'x'")
ValueError: 'label' must be of length 'x'
2020-05-02 17:38:22,132 INFO: Microblog startup [in /home/user/Documents/Scripts/microblog/app/__init__.py:46]
2020-05-02 17:38:45,498 INFO: Microblog startup [in /home/user/Documents/Scripts/microblog/app/__init__.py:46]
2020-05-02 17:40:18,679 INFO: Microblog startup [in /home/user/Documents/Scripts/microblog/app/__init__.py:46]
2020-05-02 17:40:26,447 ERROR: Exception on /disk [POST] [in /home/user/.local/lib/python3.7/site-packages/flask/app.py:1891]
Traceback (most recent call last):
  File "/home/user/.local/lib/python3.7/site-packages/flask/app.py", line 2446, in wsgi_app
    response = self.full_dispatch_request()
  File "/home/user/.local/lib/python3.7/site-packages/flask/app.py", line 1951, in full_dispatch_request
    rv = self.handle_user_exception(e)
  File "/home/user/.local/lib/python3.7/site-packages/flask/app.py", line 1820, in handle_user_exception
    reraise(exc_type, exc_value, tb)
  File "/home/user/.local/lib/python3.7/site-packages/flask/_compat.py", line 39, in reraise
    raise value
  File "/home/user/.local/lib/python3.7/site-packages/flask/app.py", line 1949, in full_dispatch_request
    rv = self.dispatch_request()
  File "/home/user/.local/lib/python3.7/site-packages/flask/app.py", line 1935, in dispatch_request
    return self.view_functions[rule.endpoint](**req.view_args)
  File "/home/user/Documents/Scripts/microblog/app/routes.py", line 208, in disk
    query = session.query(System.disk_free).filter_by(system_id='ubuntu').last()
AttributeError: 'BaseQuery' object has no attribute 'last'
2020-05-02 17:40:43,797 INFO: Microblog startup [in /home/user/Documents/Scripts/microblog/app/__init__.py:46]
2020-05-02 17:41:33,408 INFO: Microblog startup [in /home/user/Documents/Scripts/microblog/app/__init__.py:46]
2020-05-02 17:42:14,531 INFO: Microblog startup [in /home/user/Documents/Scripts/microblog/app/__init__.py:46]
2020-05-02 17:43:12,013 INFO: Microblog startup [in /home/user/Documents/Scripts/microblog/app/__init__.py:46]
2020-05-02 17:45:31,677 INFO: Microblog startup [in /home/user/Documents/Scripts/microblog/app/__init__.py:46]
2020-05-02 17:45:40,552 INFO: Microblog startup [in /home/user/Documents/Scripts/microblog/app/__init__.py:46]
2020-05-02 17:47:10,946 INFO: Microblog startup [in /home/user/Documents/Scripts/microblog/app/__init__.py:46]
2020-05-02 17:49:52,337 INFO: Microblog startup [in /home/user/Documents/Scripts/microblog/app/__init__.py:46]
2020-05-02 17:52:48,874 INFO: Microblog startup [in /home/user/Documents/Scripts/microblog/app/__init__.py:46]
2020-05-02 17:53:53,039 INFO: Microblog startup [in /home/user/Documents/Scripts/microblog/app/__init__.py:46]
2020-05-02 17:56:00,906 INFO: Microblog startup [in /home/user/Documents/Scripts/microblog/app/__init__.py:46]
2020-05-02 17:59:04,200 INFO: Microblog startup [in /home/user/Documents/Scripts/microblog/app/__init__.py:46]
2020-05-02 18:00:38,878 INFO: Microblog startup [in /home/user/Documents/Scripts/microblog/app/__init__.py:46]
2020-05-02 18:04:20,599 INFO: Microblog startup [in /home/user/Documents/Scripts/microblog/app/__init__.py:46]
2020-05-02 18:07:27,962 INFO: Microblog startup [in /home/user/Documents/Scripts/microblog/app/__init__.py:46]
2020-05-02 18:08:17,495 INFO: Microblog startup [in /home/user/Documents/Scripts/microblog/app/__init__.py:46]
