2020-05-12 18:22:59,509 INFO: MicroMonitor startup [in /home/user/Documents/Scripts/microblog/app/__init__.py:46]
2020-05-12 18:23:19,732 INFO: MicroMonitor startup [in /home/user/Documents/Scripts/microblog/app/__init__.py:46]
2020-05-12 18:23:20,674 ERROR: Exception on /cpu [GET] [in /home/user/.local/lib/python3.7/site-packages/flask/app.py:1891]
Traceback (most recent call last):
  File "/home/user/.local/lib/python3.7/site-packages/flask/app.py", line 2446, in wsgi_app
    response = self.full_dispatch_request()
  File "/home/user/.local/lib/python3.7/site-packages/flask/app.py", line 1951, in full_dispatch_request
    rv = self.handle_user_exception(e)
  File "/home/user/.local/lib/python3.7/site-packages/flask/app.py", line 1820, in handle_user_exception
    reraise(exc_type, exc_value, tb)
  File "/home/user/.local/lib/python3.7/site-packages/flask/_compat.py", line 39, in reraise
    raise value
  File "/home/user/.local/lib/python3.7/site-packages/flask/app.py", line 1949, in full_dispatch_request
    rv = self.dispatch_request()
  File "/home/user/.local/lib/python3.7/site-packages/flask/app.py", line 1935, in dispatch_request
    return self.view_functions[rule.endpoint](**req.view_args)
  File "/home/user/.local/lib/python3.7/site-packages/flask_login/utils.py", line 261, in decorated_view
    return func(*args, **kwargs)
  File "/home/user/Documents/Scripts/microblog/app/routes.py", line 207, in cpu
    return render_template('cpu.html', plot=html_text, systems=uniqueList)
  File "/home/user/.local/lib/python3.7/site-packages/flask/templating.py", line 140, in render_template
    ctx.app,
  File "/home/user/.local/lib/python3.7/site-packages/flask/templating.py", line 120, in _render
    rv = template.render(context)
  File "/home/user/.local/lib/python3.7/site-packages/jinja2/asyncsupport.py", line 76, in render
    return original_render(self, *args, **kwargs)
  File "/home/user/.local/lib/python3.7/site-packages/jinja2/environment.py", line 1008, in render
    return self.environment.handle_exception(exc_info, True)
  File "/home/user/.local/lib/python3.7/site-packages/jinja2/environment.py", line 780, in handle_exception
    reraise(exc_type, exc_value, tb)
  File "/home/user/.local/lib/python3.7/site-packages/jinja2/_compat.py", line 37, in reraise
    raise value.with_traceback(tb)
  File "/home/user/Documents/Scripts/microblog/app/templates/base.html", line 56, in template
    {% block app_content %}{% endblock %}
  File "/home/user/.local/lib/python3.7/site-packages/jinja2/environment.py", line 1005, in render
    return concat(self.root_render_func(self.new_context(vars)))
  File "/home/user/Documents/Scripts/microblog/app/templates/cpu.html", line 11, in root
    {% endfor %}
  File "/home/user/.local/lib/python3.7/site-packages/jinja2/environment.py", line 830, in get_template
    return self._load_template(name, self.make_globals(globals))
  File "/home/user/.local/lib/python3.7/site-packages/jinja2/environment.py", line 804, in _load_template
    template = self.loader.load(self, name, globals)
  File "/home/user/.local/lib/python3.7/site-packages/jinja2/loaders.py", line 125, in load
    code = environment.compile(source, name, filename)
  File "/home/user/.local/lib/python3.7/site-packages/jinja2/environment.py", line 591, in compile
    self.handle_exception(exc_info, source_hint=source_hint)
  File "/home/user/.local/lib/python3.7/site-packages/jinja2/environment.py", line 780, in handle_exception
    reraise(exc_type, exc_value, tb)
  File "/home/user/.local/lib/python3.7/site-packages/jinja2/_compat.py", line 37, in reraise
    raise value.with_traceback(tb)
  File "/home/user/Documents/Scripts/microblog/app/templates/base.html", line 56, in template
    {% block app_content %}{% endblock %}
  File "/home/user/.local/lib/python3.7/site-packages/jinja2/environment.py", line 543, in _generate
    optimized=self.optimized)
  File "/home/user/.local/lib/python3.7/site-packages/jinja2/compiler.py", line 82, in generate
    generator.visit(node)
  File "/home/user/.local/lib/python3.7/site-packages/jinja2/visitor.py", line 38, in visit
    return f(node, *args, **kwargs)
  File "/home/user/.local/lib/python3.7/site-packages/jinja2/compiler.py", line 718, in visit_Template
    self.fail('block %r defined twice' % block.name, block.lineno)
  File "/home/user/.local/lib/python3.7/site-packages/jinja2/compiler.py", line 315, in fail
    raise TemplateAssertionError(msg, lineno, self.name, self.filename)
jinja2.exceptions.TemplateAssertionError: block 'app_content' defined twice
2020-05-12 18:23:33,449 INFO: MicroMonitor startup [in /home/user/Documents/Scripts/microblog/app/__init__.py:46]
2020-05-12 18:30:24,226 INFO: MicroMonitor startup [in /home/user/Documents/Scripts/microblog/app/__init__.py:46]
2020-05-12 18:31:12,042 INFO: MicroMonitor startup [in /home/user/Documents/Scripts/microblog/app/__init__.py:46]
2020-05-12 18:34:04,291 INFO: MicroMonitor startup [in /home/user/Documents/Scripts/microblog/app/__init__.py:46]
2020-05-12 18:38:32,228 INFO: MicroMonitor startup [in /home/user/Documents/Scripts/microblog/app/__init__.py:46]
2020-05-12 18:38:58,953 INFO: MicroMonitor startup [in /home/user/Documents/Scripts/microblog/app/__init__.py:46]
2020-05-12 18:39:56,656 INFO: MicroMonitor startup [in /home/user/Documents/Scripts/microblog/app/__init__.py:46]
2020-05-12 18:42:07,056 INFO: MicroMonitor startup [in /home/user/Documents/Scripts/microblog/app/__init__.py:46]
2020-05-12 18:42:20,350 INFO: MicroMonitor startup [in /home/user/Documents/Scripts/microblog/app/__init__.py:46]
2020-05-12 18:45:21,430 INFO: MicroMonitor startup [in /home/user/Documents/Scripts/microblog/app/__init__.py:46]
2020-05-12 18:45:42,990 INFO: MicroMonitor startup [in /home/user/Documents/Scripts/microblog/app/__init__.py:46]
2020-05-12 19:15:07,631 INFO: MicroMonitor startup [in /home/user/Documents/Scripts/microblog/app/__init__.py:46]
2020-05-14 19:59:40,077 INFO: MicroMonitor startup [in /home/user/Documents/Scripts/microblog/app/__init__.py:46]
2020-05-14 20:00:13,589 INFO: MicroMonitor startup [in /home/user/Documents/Scripts/microblog/app/__init__.py:46]
2020-05-15 13:11:04,750 INFO: MicroMonitor startup [in /home/user/Documents/Scripts/microblog/app/__init__.py:46]
2020-05-16 14:23:56,461 INFO: MicroMonitor startup [in /home/user/Documents/Scripts/microblog/app/__init__.py:46]
2020-05-16 14:27:30,833 INFO: MicroMonitor startup [in /home/user/Documents/Scripts/microblog/app/__init__.py:46]
2020-05-16 14:41:47,284 INFO: MicroMonitor startup [in /home/user/Documents/Scripts/microblog/app/__init__.py:46]
2020-05-16 14:42:19,385 INFO: MicroMonitor startup [in /home/user/Documents/Scripts/microblog/app/__init__.py:46]
2020-05-16 14:43:11,089 ERROR: Exception on /disk [GET] [in /home/user/.local/lib/python3.7/site-packages/flask/app.py:1891]
Traceback (most recent call last):
  File "/home/user/.local/lib/python3.7/site-packages/flask/app.py", line 2446, in wsgi_app
    response = self.full_dispatch_request()
  File "/home/user/.local/lib/python3.7/site-packages/flask/app.py", line 1951, in full_dispatch_request
    rv = self.handle_user_exception(e)
  File "/home/user/.local/lib/python3.7/site-packages/flask/app.py", line 1820, in handle_user_exception
    reraise(exc_type, exc_value, tb)
  File "/home/user/.local/lib/python3.7/site-packages/flask/_compat.py", line 39, in reraise
    raise value
  File "/home/user/.local/lib/python3.7/site-packages/flask/app.py", line 1949, in full_dispatch_request
    rv = self.dispatch_request()
  File "/home/user/.local/lib/python3.7/site-packages/flask/app.py", line 1935, in dispatch_request
    return self.view_functions[rule.endpoint](**req.view_args)
  File "/home/user/.local/lib/python3.7/site-packages/flask_login/utils.py", line 261, in decorated_view
    return func(*args, **kwargs)
  File "/home/user/Documents/Scripts/microblog/app/routes.py", line 330, in disk
    legendlabels = 'Free space ' + str(get_size(query[0])), 'Used space '+ str(get_size(query2[0]))
TypeError: 'NoneType' object is not subscriptable
2020-05-16 14:43:13,369 ERROR: Exception on /memory [GET] [in /home/user/.local/lib/python3.7/site-packages/flask/app.py:1891]
Traceback (most recent call last):
  File "/home/user/.local/lib/python3.7/site-packages/flask/app.py", line 2446, in wsgi_app
    response = self.full_dispatch_request()
  File "/home/user/.local/lib/python3.7/site-packages/flask/app.py", line 1951, in full_dispatch_request
    rv = self.handle_user_exception(e)
  File "/home/user/.local/lib/python3.7/site-packages/flask/app.py", line 1820, in handle_user_exception
    reraise(exc_type, exc_value, tb)
  File "/home/user/.local/lib/python3.7/site-packages/flask/_compat.py", line 39, in reraise
    raise value
  File "/home/user/.local/lib/python3.7/site-packages/flask/app.py", line 1949, in full_dispatch_request
    rv = self.dispatch_request()
  File "/home/user/.local/lib/python3.7/site-packages/flask/app.py", line 1935, in dispatch_request
    return self.view_functions[rule.endpoint](**req.view_args)
  File "/home/user/.local/lib/python3.7/site-packages/flask_login/utils.py", line 261, in decorated_view
    return func(*args, **kwargs)
  File "/home/user/Documents/Scripts/microblog/app/routes.py", line 272, in memory
    ax.set_title(str("Memory usage for " + systemSelection + " total memory: " + str(totalquery[0])))
TypeError: 'NoneType' object is not subscriptable
